Workbook

Sheet Assumptions
A1: GDM INVENTORY SIMULATION — ASSUMPTIONS
A3: GLOBAL LOSS RATE ASSUMPTIONS
A4: Parameter | B4: Value
A5: Carryover quality loss | B5: 0.1
A6: New production quality loss | B6: 0.02
A8: PRODUCTION PARAMETERS BY ARCHETYPE × MATURITY BUCKET (sourced from historical data)
A9: Archetype | B9: Maturity Bucket | C9: YF Mean | D9: YF Std Dev | E9: CR Mean | F9: CR Std Dev
B10: ≤85 | C10: 1.0104 | D10: 0.2512 | E10: 1.0429 | F10: 0.0893
A11: Bayer - Above ground | B11: 86-95 | C11: 1.035 | D11: 0.2699 | E11: 1.0052 | F11: 0.1476
A12: Bayer - Above ground | B12: 96-105 | C12: 0.9899 | D12: 0.251 | E12: 1.029 | F12: 0.1736
A13: Bayer - Above ground | B13: 106-115 | C13: 0.9977 | D13: 0.2654 | E13: 1.0111 | F13: 0.1609
A14: Bayer - Above ground | B14: 116+ | C14: 0.9608 | D14: 0.2653 | E14: 0.9738 | F14: 0.1589
A15: Bayer - Above/below ground | B15: 86-95 | C15: 1.0632 | D15: 0.3422 | E15: 1.0428 | F15: 0.132
A16: Bayer - Above/below ground | B16: 96-105 | C16: 0.9465 | D16: 0.2648 | E16: 1.0651 | F16: 0.185
A17: Bayer - Above/below ground | B17: 106-115 | C17: 1.0429 | D17: 0.2423 | E17: 1.0136 | F17: 0.1588
A18: Bayer - Above/below ground | B18: 116+ | C18: 0.9933 | D18: 0.3286 | E18: 1.1017 | F18: 0.3412
A19: Conventional | B19: ≤85 | C19: 1.1737 | D19: 0.229 | E19: 1.0068 | F19: 0.1336
A20: Conventional | B20: 86-95 | C20: 1.098 | D20: 0.2369 | E20: 0.9667 | F20: 0.1374
A21: Conventional | B21: 96-105 | C21: 1.0489 | D21: 0.31 | E21: 0.9757 | F21: 0.1746
A22: Conventional | B22: 106-115 | C22: 0.9863 | D22: 0.2772 | E22: 0.9711 | F22: 0.155
... A33: Syngenta - Above/below ground | B33: 116+ | C33: 0.8267 | D33: 0.2324 | E33: 1.0843 | F33: 0.1556

Sheet Summary
A1: GDM INVENTORY SIMULATION — CARRYOVER INVENTORY SUMMARY (Median Sales)
A2: Archetype | B2: Maturity | C2: Year 1 | D2: Year 2 | E2: Year 3 | F2: Year 4 | G2: Year 5 | H2: Year 6 | I2: Year 7 | J2: Year 8 | K2: Year 9 | L2: Year 10
A3: Bayer - Above ground | B3: 85 | C3: =Bayer__Above_ground_85!B10 -> 10930.796 | D3: =Bayer__Above_ground_85!C10 -> 8825.6348 | E3: =Bayer__Above_ground_85!D10 -> 6492.0999 | F3: =Bayer__Above_ground_85!E10 -> 4716.7812 | G3: =Bayer__Above_ground_85!F10 -> 3171.6525 | H3: =Bayer__Above_ground_85!G10 -> 2591.2773 | I3: =Bayer__Above_ground_85!H10 -> 2332.1495 | J3: =Bayer__Above_ground_85!I10 -> 2098.9346 | ... L3: =Bayer__Above_ground_85!K10 -> 1700.137
A4: Bayer - Above ground | B4: 95 | C4: =Bayer__Above_ground_95!B10 -> 11424.262 | D4: =Bayer__Above_ground_95!C10 -> 8969.6084 | E4: =Bayer__Above_ground_95!D10 -> 6129.9606 | F4: =Bayer__Above_ground_95!E10 -> 3696.927 | G4: =Bayer__Above_ground_95!F10 -> 1483.0372 | H4: =Bayer__Above_ground_95!G10 -> 487.92542 | I4: =Bayer__Above_ground_95!H10 -> 321.02288 | J4: =Bayer__Above_ground_95!I10 -> 288.92059 | ... L4: =Bayer__Above_ground_95!K10 -> 234.02568
A5: Bayer - Above ground | B5: 105 | C5: =Bayer__Above_ground_105!B10 -> 11874.9 | D5: =Bayer__Above_ground_105!C10 -> 8926.229 | E5: =Bayer__Above_ground_105!D10 -> 5150.3525 | F5: =Bayer__Above_ground_105!E10 -> 2215.8004 | G5: =Bayer__Above_ground_105!F10 -> -649.81527 | H5: =Bayer__Above_ground_105!G10 -> -1903.9925 | I5: =Bayer__Above_ground_105!H10 -> -2188.7832 | J5: =Bayer__Above_ground_105!I10 -> -1969.9049 | ... L5: =Bayer__Above_ground_105!K10 -> -1595.623
A6: Bayer - Above ground | B6: 115 | C6: =Bayer__Above_ground_115!B10 -> 12371.268 | D6: =Bayer__Above_ground_115!C10 -> 9528.9435 | E6: =Bayer__Above_ground_115!D10 -> 5248.0101 | F6: =Bayer__Above_ground_115!E10 -> 2006.3073 | G6: =Bayer__Above_ground_115!F10 -> -946.4511 | H6: =Bayer__Above_ground_115!G10 -> -2192.745 | I6: =Bayer__Above_ground_115!H10 -> -2430.3605 | J6: =Bayer__Above_ground_115!I10 -> -2187.3245 | ... L6: =Bayer__Above_ground_115!K10 -> -1771.7328
A7: Bayer - Above/below ground | B7: 85 | C7: =Bayer__Above_below_85!B10 -> 10237.083 | D7: =Bayer__Above_below_85!C10 -> 8023.8927 | E7: =Bayer__Above_below_85!D10 -> 5854.498 | F7: =Bayer__Above_below_85!E10 -> 4308.7226 | G7: =Bayer__Above_below_85!F10 -> 3100.1811 | H7: =Bayer__Above_below_85!G10 -> 2622.703 | I7: =Bayer__Above_below_85!H10 -> 2360.4327 | J7: =Bayer__Above_below_85!I10 -> 2124.3895 | ... L7: =Bayer__Above_below_85!K10 -> 1720.7555
A8: Bayer - Above/below ground | B8: 95 | C8: =Bayer__Above_below_95!B10 -> 11180.416 | D8: =Bayer__Above_below_95!C10 -> 8900.9989 | E8: =Bayer__Above_below_95!D10 -> 6334.4703 | F8: =Bayer__Above_below_95!E10 -> 4553.5002 | G8: =Bayer__Above_below_95!F10 -> 3013.4199 | H8: =Bayer__Above_below_95!G10 -> 2250.0227 | I8: =Bayer__Above_below_95!H10 -> 2021.9604 | J8: =Bayer__Above_below_95!I10 -> 1819.7644 | ... L8: =Bayer__Above_below_95!K10 -> 1474.0092
A9: Bayer - Above/below ground | B9: 105 | C9: =Bayer__Above_below_105!B10 -> 11402.535 | D9: =Bayer__Above_below_105!C10 -> 8370.497 | E9: =Bayer__Above_below_105!D10 -> 4755.6581 | F9: =Bayer__Above_below_105!E10 -> 2106.9946 | G9: =Bayer__Above_below_105!F10 -> -264.23116 | H9: =Bayer__Above_below_105!G10 -> -1176.2969 | I9: =Bayer__Above_below_105!H10 -> -1312.6172 | J9: =Bayer__Above_below_105!I10 -> -1181.3555 | ... L9: =Bayer__Above_below_105!K10 -> -956.89796
A10: Bayer - Above/below ground | B10: 115 | C10: =Bayer__Above_below_115!B10 -> 12291.015 | D10: =Bayer__Above_below_115!C10 -> 9364.2245 | E10: =Bayer__Above_below_115!D10 -> 5997.8373 | F10: =Bayer__Above_below_115!E10 -> 3299.1788 | G10: =Bayer__Above_below_115!F10 -> 920.29419 | H10: =Bayer__Above_below_115!G10 -> -147.6646 | I10: =Bayer__Above_below_115!H10 -> -385.26814 | J10: =Bayer__Above_below_115!I10 -> -346.74133 | ... L10: =Bayer__Above_below_115!K10 -> -280.86047
A11: Conventional | B11: 85 | C11: =Conventional_85!B10 -> 10696.141 | D11: =Conventional_85!C10 -> 9244.2488 | E11: =Conventional_85!D10 -> 7582.595 | F11: =Conventional_85!E10 -> 6251.1486 | G11: =Conventional_85!F10 -> 5137.8427 | H11: =Conventional_85!G10 -> 4599.7684 | I11: =Conventional_85!H10 -> 4139.7916 | J11: =Conventional_85!I10 -> 3725.8124 | ... L11: =Conventional_85!K10 -> 3017.9081
A12: Conventional | B12: 95 | C12: =Conventional_95!B10 -> 10588.889 | D12: =Conventional_95!C10 -> 8702.1447 | E12: =Conventional_95!D10 -> 6675.6414 | F12: =Conventional_95!E10 -> 5184.549 | G12: =Conventional_95!F10 -> 3972.031 | H12: =Conventional_95!G10 -> 3464.7279 | I12: =Conventional_95!H10 -> 3118.2551 | J12: =Conventional_95!I10 -> 2806.4296 | ... L12: =Conventional_95!K10 -> 2273.2079
A13: Conventional | B13: 105 | C13: =Conventional_105!B10 -> 10085.373 | D13: =Conventional_105!C10 -> 8004.3021 | E13: =Conventional_105!D10 -> 5908.0254 | F13: =Conventional_105!E10 -> 4320.5529 | G13: =Conventional_105!F10 -> 2994.9755 | H13: =Conventional_105!G10 -> 2458.378 | I13: =Conventional_105!H10 -> 2212.5402 | J13: =Conventional_105!I10 -> 1991.2861 | ... L13: =Conventional_105!K10 -> 1612.9418
A14: Conventional | B14: 115 | C14: =Conventional_115!B10 -> 10092.35 | D14: =Conventional_115!C10 -> 7708.3714 | E14: =Conventional_115!D10 -> 5461.9126 | F14: =Conventional_115!E10 -> 3747.8771 | G14: =Conventional_115!F10 -> 2451.4487 | H14: =Conventional_115!G10 -> 1959.7138 | I14: =Conventional_115!H10 -> 1763.7424 | J14: =Conventional_115!I10 -> 1587.3682 | ... L14: =Conventional_115!K10 -> 1285.7682
A15: Syngenta - Above ground | B15: 85 | C15: =Syngenta__Above_gr_85!B10 -> 9000 | D15: =Syngenta__Above_gr_85!C10 -> 8100 | E15: =Syngenta__Above_gr_85!D10 -> 7290 | F15: =Syngenta__Above_gr_85!E10 -> 6561 | G15: =Syngenta__Above_gr_85!F10 -> 5904.9 | H15: =Syngenta__Above_gr_85!G10 -> 5314.41 | I15: =Syngenta__Above_gr_85!H10 -> 4782.969 | J15: =Syngenta__Above_gr_85!I10 -> 4304.6721 | ... L15: =Syngenta__Above_gr_85!K10 -> 3486.7844
A16: Syngenta - Above ground | B16: 95 | C16: =Syngenta__Above_gr_95!B10 -> 9000 | D16: =Syngenta__Above_gr_95!C10 -> 8100 | E16: =Syngenta__Above_gr_95!D10 -> 7290 | F16: =Syngenta__Above_gr_95!E10 -> 6561 | G16: =Syngenta__Above_gr_95!F10 -> 5904.9 | H16: =Syngenta__Above_gr_95!G10 -> 5314.41 | I16: =Syngenta__Above_gr_95!H10 -> 4782.969 | J16: =Syngenta__Above_gr_95!I10 -> 4304.6721 | ... L16: =Syngenta__Above_gr_95!K10 -> 3486.7844
A17: Syngenta - Above ground | B17: 105 | C17: =Syngenta__Above_gr_105!B10 -> 9000 | D17: =Syngenta__Above_gr_105!C10 -> 8100 | E17: =Syngenta__Above_gr_105!D10 -> 7290 | F17: =Syngenta__Above_gr_105!E10 -> 6561 | G17: =Syngenta__Above_gr_105!F10 -> 5904.9 | H17: =Syngenta__Above_gr_105!G10 -> 5314.41 | I17: =Syngenta__Above_gr_105!H10 -> 4782.969 | J17: =Syngenta__Above_gr_105!I10 -> 4304.6721 | ... L17: =Syngenta__Above_gr_105!K10 -> 3486.7844
A18: Syngenta - Above ground | B18: 115 | C18: =Syngenta__Above_gr_115!B10 -> 9000 | D18: =Syngenta__Above_gr_115!C10 -> 8100 | E18: =Syngenta__Above_gr_115!D10 -> 7290 | F18: =Syngenta__Above_gr_115!E10 -> 6561 | G18: =Syngenta__Above_gr_115!F10 -> 5904.9 | H18: =Syngenta__Above_gr_115!G10 -> 5314.41 | I18: =Syngenta__Above_gr_115!H10 -> 4782.969 | J18: =Syngenta__Above_gr_115!I10 -> 4304.6721 | ... L18: =Syngenta__Above_gr_115!K10 -> 3486.7844
A19: Syngenta - Above/below ground | B19: 85 | C19: =Syngenta__Above_be_85!B10 -> 9000 | D19: =Syngenta__Above_be_85!C10 -> 8100 | E19: =Syngenta__Above_be_85!D10 -> 7290 | F19: =Syngenta__Above_be_85!E10 -> 6561 | G19: =Syngenta__Above_be_85!F10 -> 5904.9 | H19: =Syngenta__Above_be_85!G10 -> 5314.41 | I19: =Syngenta__Above_be_85!H10 -> 4782.969 | J19: =Syngenta__Above_be_85!I10 -> 4304.6721 | ... L19: =Syngenta__Above_be_85!K10 -> 3486.7844
A20: Syngenta - Above/below ground | B20: 95 | C20: =Syngenta__Above_be_95!B10 -> 9000 | D20: =Syngenta__Above_be_95!C10 -> 8100 | E20: =Syngenta__Above_be_95!D10 -> 7290 | F20: =Syngenta__Above_be_95!E10 -> 6561 | G20: =Syngenta__Above_be_95!F10 -> 5904.9 | H20: =Syngenta__Above_be_95!G10 -> 5314.41 | I20: =Syngenta__Above_be_95!H10 -> 4782.969 | J20: =Syngenta__Above_be_95!I10 -> 4304.6721 | ... L20: =Syngenta__Above_be_95!K10 -> 3486.7844
A21: Syngenta - Above/below ground | B21: 105 | C21: =Syngenta__Above_be_105!B10 -> 9000 | D21: =Syngenta__Above_be_105!C10 -> 8100 | E21: =Syngenta__Above_be_105!D10 -> 7290 | F21: =Syngenta__Above_be_105!E10 -> 6561 | G21: =Syngenta__Above_be_105!F10 -> 5904.9 | H21: =Syngenta__Above_be_105!G10 -> 5314.41 | I21: =Syngenta__Above_be_105!H10 -> 4782.969 | J21: =Syngenta__Above_be_105!I10 -> 4304.6721 | ... L21: =Syngenta__Above_be_105!K10 -> 3486.7844
A22: Syngenta - Above/below ground | B22: 115 | C22: =Syngenta__Above_be_115!B10 -> 9000 | D22: =Syngenta__Above_be_115!C10 -> 8100 | E22: =Syngenta__Above_be_115!D10 -> 7290 | F22: =Syngenta__Above_be_115!E10 -> 6561 | G22: =Syngenta__Above_be_115!F10 -> 5904.9 | H22: =Syngenta__Above_be_115!G10 -> 5314.41 | I22: =Syngenta__Above_be_115!H10 -> 4782.969 | J22: =Syngenta__Above_be_115!I10 -> 4304.6721 | ... L22: =Syngenta__Above_be_115!K10 -> 3486.7844

Sheet Bayer__Above_ground_85
A1: INVENTORY LIFECYCLE | Bayer - Above ground | Maturity 85 | Median Sales
A2: Line Item | B2: Year 1 | C2: Year 2 | D2: Year 3 | E2: Year 4 | F2: Year 5 | G2: Year 6 | H2: Year 7 | I2: Year 8 | J2: Year 9 | K2: Year 10
A3: Carryover inventory from prior year | B3: 10000 | C3: =B10 -> 10930.796 | D3: =C10 -> 8825.6348 | E3: =D10 -> 6492.0999 | F3: =E10 -> 4716.7812 | G3: =F10 -> 3171.6525 | H3: =G10 -> 2591.2773 | I3: =H10 -> 2332.1495 | J3: =I10 -> 2098.9346 | K3: =J10 -> 1889.0411
A4: Carryover quality loss (10%) | B4: =-B3*Assumptions!$B$5 -> -1000 | C4: =-C3*Assumptions!$B$5 -> -1093.0796 | D4: =-D3*Assumptions!$B$5 -> -882.56348 | E4: =-E3*Assumptions!$B$5 -> -649.20999 | F4: =-F3*Assumptions!$B$5 -> -471.67812 | G4: =-G3*Assumptions!$B$5 -> -317.16525 | H4: =-H3*Assumptions!$B$5 -> -259.12773 | I4: =-I3*Assumptions!$B$5 -> -233.21495 | ... K4: =-K3*Assumptions!$B$5 -> -188.90411
A5: Planned production (= next yr sales) | B5: 5192.82 | C5: 4048.47 | D5: 2515.32 | E5: 1345.26 | F5: 263.21 | G5: 0 | H5: 0 | I5: 0 | J5: 0 | K5: 0
A6: New production (after yield & conv.) | B6: =B5*$B$13*$B$14 -> 5471.9141 | C6: =C5*$B$13*$B$14 -> 4266.0597 | D6: =D5*$B$13*$B$14 -> 2650.5088 | E6: =E5*$B$13*$B$14 -> 1417.5626 | F6: =F5*$B$13*$B$14 -> 277.35653 | G6: =G5*$B$13*$B$14 -> 0 | H6: =H5*$B$13*$B$14 -> 0 | I6: =I5*$B$13*$B$14 -> 0 | ... K6: =K5*$B$13*$B$14 -> 0
A7: Production quality loss (2%) | B7: =-B6*Assumptions!$B$6 -> -109.43828 | C7: =-C6*Assumptions!$B$6 -> -85.321194 | D7: =-D6*Assumptions!$B$6 -> -53.010176 | E7: =-E6*Assumptions!$B$6 -> -28.351251 | F7: =-F6*Assumptions!$B$6 -> -5.5471305 | G7: =-G6*Assumptions!$B$6 -> 0 | H7: =-H6*Assumptions!$B$6 -> 0 | I7: =-I6*Assumptions!$B$6 -> 0 | ... K7: =-K6*Assumptions!$B$6 -> 0
A8: Total saleable inventory | B8: =B3+B4+B6+B7 -> 14362.476 | C8: =C3+C4+C6+C7 -> 14018.455 | D8: =D3+D4+D6+D7 -> 10540.57 | E8: =E3+E4+E6+E7 -> 7232.1012 | F8: =F3+F4+F6+F7 -> 4516.9125 | G8: =G3+G4+G6+G7 -> 2854.4873 | H8: =H3+H4+H6+H7 -> 2332.1495 | I8: =I3+I4+I6+I7 -> 2098.9346 | ... K8: =K3+K4+K6+K7 -> 1700.137
A9: Sales | B9: 3431.68 | C9: 5192.82 | D9: 4048.47 | E9: 2515.32 | F9: 1345.26 | G9: 263.21 | H9: 0 | I9: 0 | J9: 0 | K9: 0
A10: Remaining inventory (carryover out) | B10: =B8-B9 -> 10930.796 | C10: =C8-C9 -> 8825.6348 | D10: =D8-D9 -> 6492.0999 | E10: =E8-E9 -> 4716.7812 | F10: =F8-F9 -> 3171.6525 | G10: =G8-G9 -> 2591.2773 | H10: =H8-H9 -> 2332.1495 | I10: =I8-I9 -> 2098.9346 | ... K10: =K8-K9 -> 1700.137
A12: Production Parameters Used
A13: Yield Factor (Mean) | B13: 1.0104
A14: Conversion Rate (Mean) | B14: 1.0429

Sheet Bayer__Above_ground_95
A1: INVENTORY LIFECYCLE | Bayer - Above ground | Maturity 95 | Median Sales
A2: Line Item | B2: Year 1 | C2: Year 2 | D2: Year 3 | E2: Year 4 | F2: Year 5 | G2: Year 6 | H2: Year 7 | I2: Year 8 | J2: Year 9 | K2: Year 10
A3: Carryover inventory from prior year | B3: 10000 | C3: =B10 -> 11424.262 | D3: =C10 -> 8969.6084 | E3: =D10 -> 6129.9606 | F3: =E10 -> 3696.927 | G3: =F10 -> 1483.0372 | H3: =G10 -> 487.92542 | I3: =H10 -> 321.02288 | J3: =I10 -> 288.92059 | K3: =J10 -> 260.02853
A4: Carryover quality loss (10%) | B4: =-B3*Assumptions!$B$5 -> -1000 | C4: =-C3*Assumptions!$B$5 -> -1142.4262 | D4: =-D3*Assumptions!$B$5 -> -896.96084 | E4: =-E3*Assumptions!$B$5 -> -612.99606 | F4: =-F3*Assumptions!$B$5 -> -369.6927 | G4: =-G3*Assumptions!$B$5 -> -148.30372 | H4: =-H3*Assumptions!$B$5 -> -48.792542 | I4: =-I3*Assumptions!$B$5 -> -32.102288 | ... K4: =-K3*Assumptions!$B$5 -> -26.002853
A5: Planned production (= next yr sales) | B5: 8184.77 | C5: 6740.6 | D5: 4705.8 | E5: 2830.36 | F5: 967.23 | G5: 118.11 | H5: 0 | I5: 0 | J5: 0 | K5: 0
A6: New production (after yield & conv.) | B6: =B5*$B$13*$B$14 -> 8515.2874 | C6: =C5*$B$13*$B$14 -> 7012.7989 | D6: =D5*$B$13*$B$14 -> 4895.8296 | E6: =E5*$B$13*$B$14 -> 2944.6556 | F6: =F5*$B$13*$B$14 -> 1006.2887 | G6: =G5*$B$13*$B$14 -> 122.87952 | H6: =H5*$B$13*$B$14 -> 0 | I6: =I5*$B$13*$B$14 -> 0 | ... K6: =K5*$B$13*$B$14 -> 0
A7: Production quality loss (2%) | B7: =-B6*Assumptions!$B$6 -> -170.30575 | C7: =-C6*Assumptions!$B$6 -> -140.25598 | D7: =-D6*Assumptions!$B$6 -> -97.916592 | E7: =-E6*Assumptions!$B$6 -> -58.893112 | F7: =-F6*Assumptions!$B$6 -> -20.125774 | G7: =-G6*Assumptions!$B$6 -> -2.4575904 | H7: =-H6*Assumptions!$B$6 -> 0 | I7: =-I6*Assumptions!$B$6 -> 0 | ... K7: =-K6*Assumptions!$B$6 -> 0
A8: Total saleable inventory | B8: =B3+B4+B6+B7 -> 17344.982 | C8: =C3+C4+C6+C7 -> 17154.378 | D8: =D3+D4+D6+D7 -> 12870.561 | E8: =E3+E4+E6+E7 -> 8402.727 | F8: =F3+F4+F6+F7 -> 4313.3972 | G8: =G3+G4+G6+G7 -> 1455.1554 | H8: =H3+H4+H6+H7 -> 439.13288 | I8: =I3+I4+I6+I7 -> 288.92059 | ... K8: =K3+K4+K6+K7 -> 234.02568
A9: Sales | B9: 5920.72 | C9: 8184.77 | D9: 6740.6 | E9: 4705.8 | F9: 2830.36 | G9: 967.23 | H9: 118.11 | I9: 0 | J9: 0 | K9: 0
A10: Remaining inventory (carryover out) | B10: =B8-B9 -> 11424.262 | C10: =C8-C9 -> 8969.6084 | D10: =D8-D9 -> 6129.9606 | E10: =E8-E9 -> 3696.927 | F10: =F8-F9 -> 1483.0372 | G10: =G8-G9 -> 487.92542 | H10: =H8-H9 -> 321.02288 | I10: =I8-I9 -> 288.92059 | ... K10: =K8-K9 -> 234.02568
A12: Production Parameters Used
A13: Yield Factor (Mean) | B13: 1.035
A14: Conversion Rate (Mean) | B14: 1.0052

Sheet Bayer__Above_ground_105
A1: INVENTORY LIFECYCLE | Bayer - Above ground | Maturity 105 | Median Sales
A2: Line Item | B2: Year 1 | C2: Year 2 | D2: Year 3 | E2: Year 4 | F2: Year 5 | G2: Year 6 | H2: Year 7 | I2: Year 8 | J2: Year 9 | K2: Year 10
A3: Carryover inventory from prior year | B3: 10000 | C3: =B10 -> 11874.9 | D3: =C10 -> 8926.229 | E3: =D10 -> 5150.3525 | F3: =E10 -> 2215.8004 | G3: =F10 -> -649.81527 | H3: =G10 -> -1903.9925 | I3: =H10 -> -2188.7832 | J3: =I10 -> -1969.9049 | K3: =J10 -> -1772.9144
A4: Carryover quality loss (10%) | B4: =-B3*Assumptions!$B$5 -> -1000 | C4: =-C3*Assumptions!$B$5 -> -1187.49 | D4: =-D3*Assumptions!$B$5 -> -892.6229 | E4: =-E3*Assumptions!$B$5 -> -515.03525 | F4: =-F3*Assumptions!$B$5 -> -221.58004 | G4: =-G3*Assumptions!$B$5 -> 64.981527 | H4: =-H3*Assumptions!$B$5 -> 190.39925 | I4: =-I3*Assumptions!$B$5 -> 218.87832 | ... K4: =-K3*Assumptions!$B$5 -> 177.29144
A5: Planned production (= next yr sales) | B5: 11461.27 | C5: 9717.24 | D5: 6846.07 | E5: 4434.38 | F5: 1793.51 | G5: 475.19 | H5: 0 | I5: 0 | J5: 0 | K5: 0
A6: New production (after yield & conv.) | B6: =B5*$B$13*$B$14 -> 11674.531 | C6: =C5*$B$13*$B$14 -> 9898.0497 | D6: =D5*$B$13*$B$14 -> 6973.4555 | E6: =E5*$B$13*$B$14 -> 4516.891 | F6: =F5*$B$13*$B$14 -> 1826.882 | G6: =G5*$B$13*$B$14 -> 484.03191 | H6: =H5*$B$13*$B$14 -> 0 | I6: =I5*$B$13*$B$14 -> 0 | ... K6: =K5*$B$13*$B$14 -> 0
A7: Production quality loss (2%) | B7: =-B6*Assumptions!$B$6 -> -233.49062 | C7: =-C6*Assumptions!$B$6 -> -197.96099 | D7: =-D6*Assumptions!$B$6 -> -139.46911 | E7: =-E6*Assumptions!$B$6 -> -90.337819 | F7: =-F6*Assumptions!$B$6 -> -36.53764 | G7: =-G6*Assumptions!$B$6 -> -9.6806382 | H7: =-H6*Assumptions!$B$6 -> 0 | I7: =-I6*Assumptions!$B$6 -> 0 | ... K7: =-K6*Assumptions!$B$6 -> 0
A8: Total saleable inventory | B8: =B3+B4+B6+B7 -> 20441.04 | C8: =C3+C4+C6+C7 -> 20387.499 | D8: =D3+D4+D6+D7 -> 14867.593 | E8: =E3+E4+E6+E7 -> 9061.8704 | F8: =F3+F4+F6+F7 -> 3784.5647 | G8: =G3+G4+G6+G7 -> -110.48248 | H8: =H3+H4+H6+H7 -> -1713.5932 | I8: =I3+I4+I6+I7 -> -1969.9049 | ... K8: =K3+K4+K6+K7 -> -1595.623
A9: Sales | B9: 8566.14 | C9: 11461.27 | D9: 9717.24 | E9: 6846.07 | F9: 4434.38 | G9: 1793.51 | H9: 475.19 | I9: 0 | J9: 0 | K9: 0
A10: Remaining inventory (carryover out) | B10: =B8-B9 -> 11874.9 | C10: =C8-C9 -> 8926.229 | D10: =D8-D9 -> 5150.3525 | E10: =E8-E9 -> 2215.8004 | F10: =F8-F9 -> -649.81527 | G10: =G8-G9 -> -1903.9925 | H10: =H8-H9 -> -2188.7832 | I10: =I8-I9 -> -1969.9049 | ... K10: =K8-K9 -> -1595.623
A12: Production Parameters Used
A13: Yield Factor (Mean) | B13: 0.9899
A14: Conversion Rate (Mean) | B14: 1.029

Sheet Bayer__Above_ground_115
A1: INVENTORY LIFECYCLE | Bayer - Above ground | Maturity 115 | Median Sales
A2: Line Item | B2: Year 1 | C2: Year 2 | D2: Year 3 | E2: Year 4 | F2: Year 5 | G2: Year 6 | H2: Year 7 | I2: Year 8 | J2: Year 9 | K2: Year 10
A3: Carryover inventory from prior year | B3: 10000 | C3: =B10 -> 12371.268 | D3: =C10 -> 9528.9435 | E3: =D10 -> 5248.0101 | F3: =E10 -> 2006.3073 | G3: =F10 -> -946.4511 | H3: =G10 -> -2192.745 | I3: =H10 -> -2430.3605 | J3: =I10 -> -2187.3245 | K3: =J10 -> -1968.592
A4: Carryover quality loss (10%) | B4: =-B3*Assumptions!$B$5 -> -1000 | C4: =-C3*Assumptions!$B$5 -> -1237.1268 | D4: =-D3*Assumptions!$B$5 -> -952.89435 | E4: =-E3*Assumptions!$B$5 -> -524.80101 | F4: =-F3*Assumptions!$B$5 -> -200.63073 | G4: =-G3*Assumptions!$B$5 -> 94.64511 | H4: =-H3*Assumptions!$B$5 -> 219.2745 | I4: =-I3*Assumptions!$B$5 -> 243.03605 | ... K4: =-K3*Assumptions!$B$5 -> 196.8592
A5: Planned production (= next yr sales) | B5: 11921.92 | C5: 10435.7 | D5: 7189.63 | E5: 4524.31 | F5: 1792.62 | G5: 456.89 | H5: 0 | I5: 0 | J5: 0 | K5: 0
A6: New production (after yield & conv.) | B6: =B5*$B$13*$B$14 -> 12026.529 | C6: =C5*$B$13*$B$14 -> 10527.268 | D6: =D5*$B$13*$B$14 -> 7252.7152 | E6: =E5*$B$13*$B$14 -> 4564.0084 | F6: =F5*$B$13*$B$14 -> 1808.3493 | G6: =G5*$B$13*$B$14 -> 460.89897 | H6: =H5*$B$13*$B$14 -> 0 | I6: =I5*$B$13*$B$14 -> 0 | ... K6: =K5*$B$13*$B$14 -> 0
A7: Production quality loss (2%) | B7: =-B6*Assumptions!$B$6 -> -240.53057 | C7: =-C6*Assumptions!$B$6 -> -210.54535 | D7: =-D6*Assumptions!$B$6 -> -145.0543 | E7: =-E6*Assumptions!$B$6 -> -91.280168 | F7: =-F6*Assumptions!$B$6 -> -36.166986 | G7: =-G6*Assumptions!$B$6 -> -9.2179794 | H7: =-H6*Assumptions!$B$6 -> 0 | I7: =-I6*Assumptions!$B$6 -> 0 | ... K7: =-K6*Assumptions!$B$6 -> 0
A8: Total saleable inventory | B8: =B3+B4+B6+B7 -> 20785.998 | C8: =C3+C4+C6+C7 -> 21450.864 | D8: =D3+D4+D6+D7 -> 15683.71 | E8: =E3+E4+E6+E7 -> 9195.9373 | F8: =F3+F4+F6+F7 -> 3577.8589 | G8: =G3+G4+G6+G7 -> -400.125 | H8: =H3+H4+H6+H7 -> -1973.4705 | I8: =I3+I4+I6+I7 -> -2187.3245 | ... K8: =K3+K4+K6+K7 -> -1771.7328
A9: Sales | B9: 8414.73 | C9: 11921.92 | D9: 10435.7 | E9: 7189.63 | F9: 4524.31 | G9: 1792.62 | H9: 456.89 | I9: 0 | J9: 0 | K9: 0
A10: Remaining inventory (carryover out) | B10: =B8-B9 -> 12371.268 | C10: =C8-C9 -> 9528.9435 | D10: =D8-D9 -> 5248.0101 | E10: =E8-E9 -> 2006.3073 | F10: =F8-F9 -> -946.4511 | G10: =G8-G9 -> -2192.745 | H10: =H8-H9 -> -2430.3605 | I10: =I8-I9 -> -2187.3245 | ... K10: =K8-K9 -> -1771.7328
A12: Production Parameters Used
A13: Yield Factor (Mean) | B13: 0.9977
A14: Conversion Rate (Mean) | B14: 1.0111

Sheet Bayer__Above_below_85
A1: INVENTORY LIFECYCLE | Bayer - Above/below ground | Maturity 85 | Median Sales
A2: Line Item | B2: Year 1 | C2: Year 2 | D2: Year 3 | E2: Year 4 | F2: Year 5 | G2: Year 6 | H2: Year 7 | I2: Year 8 | J2: Year 9 | K2: Year 10
A3: Carryover inventory from prior year | B3: 10000 | C3: =B10 -> 10237.083 | D3: =C10 -> 8023.8927 | E3: =D10 -> 5854.498 | F3: =E10 -> 4308.7226 | G3: =F10 -> 3100.1811 | H3: =G10 -> 2622.703 | I3: =H10 -> 2360.4327 | J3: =I10 -> 2124.3895 | K3: =J10 -> 1911.9505
A4: Carryover quality loss (10%) | B4: =-B3*Assumptions!$B$5 -> -1000 | C4: =-C3*Assumptions!$B$5 -> -1023.7083 | D4: =-D3*Assumptions!$B$5 -> -802.38927 | E4: =-E3*Assumptions!$B$5 -> -585.4498 | F4: =-F3*Assumptions!$B$5 -> -430.87226 | G4: =-G3*Assumptions!$B$5 -> -310.01811 | H4: =-H3*Assumptions!$B$5 -> -262.2703 | I4: =-I3*Assumptions!$B$5 -> -236.04327 | ... K4: =-K3*Assumptions!$B$5 -> -191.19505
A5: Planned production (= next yr sales) | B5: 4337.84 | C5: 3212.61 | D5: 1883.27 | E5: 941.78 | F5: 167.46 | G5: 0 | H5: 0 | I5: 0 | J5: 0 | K5: 0
A6: New production (after yield & conv.) | B6: =B5*$B$13*$B$14 -> 4337.84 | C6: =C5*$B$13*$B$14 -> 3212.61 | D6: =D5*$B$13*$B$14 -> 1883.27 | E6: =E5*$B$13*$B$14 -> 941.78 | F6: =F5*$B$13*$B$14 -> 167.46 | G6: =G5*$B$13*$B$14 -> 0 | H6: =H5*$B$13*$B$14 -> 0 | I6: =I5*$B$13*$B$14 -> 0 | ... K6: =K5*$B$13*$B$14 -> 0
A7: Production quality loss (2%) | B7: =-B6*Assumptions!$B$6 -> -86.7568 | C7: =-C6*Assumptions!$B$6 -> -64.2522 | D7: =-D6*Assumptions!$B$6 -> -37.6654 | E7: =-E6*Assumptions!$B$6 -> -18.8356 | F7: =-F6*Assumptions!$B$6 -> -3.3492 | G7: =-G6*Assumptions!$B$6 -> 0 | H7: =-H6*Assumptions!$B$6 -> 0 | I7: =-I6*Assumptions!$B$6 -> 0 | ... K7: =-K6*Assumptions!$B$6 -> 0
A8: Total saleable inventory | B8: =B3+B4+B6+B7 -> 13251.083 | C8: =C3+C4+C6+C7 -> 12361.733 | D8: =D3+D4+D6+D7 -> 9067.108 | E8: =E3+E4+E6+E7 -> 6191.9926 | F8: =F3+F4+F6+F7 -> 4041.9611 | G8: =G3+G4+G6+G7 -> 2790.163 | H8: =H3+H4+H6+H7 -> 2360.4327 | I8: =I3+I4+I6+I7 -> 2124.3895 | ... K8: =K3+K4+K6+K7 -> 1720.7555
A9: Sales | B9: 3014 | C9: 4337.84 | D9: 3212.61 | E9: 1883.27 | F9: 941.78 | G9: 167.46 | H9: 0 | I9: 0 | J9: 0 | K9: 0
A10: Remaining inventory (carryover out) | B10: =B8-B9 -> 10237.083 | C10: =C8-C9 -> 8023.8927 | D10: =D8-D9 -> 5854.498 | E10: =E8-E9 -> 4308.7226 | F10: =F8-F9 -> 3100.1811 | G10: =G8-G9 -> 2622.703 | H10: =H8-H9 -> 2360.4327 | I10: =I8-I9 -> 2124.3895 | ... K10: =K8-K9 -> 1720.7555
A12: Production Parameters Used
A13: Yield Factor (Mean) | B13: 1
A14: Conversion Rate (Mean) | B14: 1

Sheet Bayer__Above_below_95
A1: INVENTORY LIFECYCLE | Bayer - Above/below ground | Maturity 95 | Median Sales
A2: Line Item | B2: Year 1 | C2: Year 2 | D2: Year 3 | E2: Year 4 | F2: Year 5 | G2: Year 6 | H2: Year 7 | I2: Year 8 | J2: Year 9 | K2: Year 10
A3: Carryover inventory from prior year | B3: 10000 | C3: =B10 -> 11180.416 | D3: =C10 -> 8900.9989 | E3: =D10 -> 6334.4703 | F3: =E10 -> 4553.5002 | G3: =F10 -> 3013.4199 | H3: =G10 -> 2250.0227 | I3: =H10 -> 2021.9604 | J3: =I10 -> 1819.7644 | K3: =J10 -> 1637.7879
A4: Carryover quality loss (10%) | B4: =-B3*Assumptions!$B$5 -> -1000 | C4: =-C3*Assumptions!$B$5 -> -1118.0416 | D4: =-D3*Assumptions!$B$5 -> -890.09989 | E4: =-E3*Assumptions!$B$5 -> -633.44703 | F4: =-F3*Assumptions!$B$5 -> -455.35002 | G4: =-G3*Assumptions!$B$5 -> -301.34199 | H4: =-H3*Assumptions!$B$5 -> -225.00227 | I4: =-I3*Assumptions!$B$5 -> -202.19604 | ... K4: =-K3*Assumptions!$B$5 -> -163.77879
A5: Planned production (= next yr sales) | B5: 6377.56 | C5: 4800.77 | D5: 2875.52 | E5: 1590.38 | F5: 465.38 | G5: 3.06 | H5: 0 | I5: 0 | J5: 0 | K5: 0
A6: New production (after yield & conv.) | B6: =B5*$B$13*$B$14 -> 7070.8324 | C6: =C5*$B$13*$B$14 -> 5322.6375 | D6: =D5*$B$13*$B$14 -> 3188.1033 | E6: =E5*$B$13*$B$14 -> 1763.2622 | F6: =F5*$B$13*$B$14 -> 515.96911 | G6: =G5*$B$13*$B$14 -> 3.3926372 | H6: =H5*$B$13*$B$14 -> 0 | I6: =I5*$B$13*$B$14 -> 0 | ... K6: =K5*$B$13*$B$14 -> 0
A7: Production quality loss (2%) | B7: =-B6*Assumptions!$B$6 -> -141.41665 | C7: =-C6*Assumptions!$B$6 -> -106.45275 | D7: =-D6*Assumptions!$B$6 -> -63.762066 | E7: =-E6*Assumptions!$B$6 -> -35.265244 | F7: =-F6*Assumptions!$B$6 -> -10.319382 | G7: =-G6*Assumptions!$B$6 -> -0.067852744 | H7: =-H6*Assumptions!$B$6 -> 0 | I7: =-I6*Assumptions!$B$6 -> 0 | ... K7: =-K6*Assumptions!$B$6 -> 0
A8: Total saleable inventory | B8: =B3+B4+B6+B7 -> 15929.416 | C8: =C3+C4+C6+C7 -> 15278.559 | D8: =D3+D4+D6+D7 -> 11135.24 | E8: =E3+E4+E6+E7 -> 7429.0202 | F8: =F3+F4+F6+F7 -> 4603.7999 | G8: =G3+G4+G6+G7 -> 2715.4027 | H8: =H3+H4+H6+H7 -> 2025.0204 | I8: =I3+I4+I6+I7 -> 1819.7644 | ... K8: =K3+K4+K6+K7 -> 1474.0092
A9: Sales | B9: 4749 | C9: 6377.56 | D9: 4800.77 | E9: 2875.52 | F9: 1590.38 | G9: 465.38 | H9: 3.06 | I9: 0 | J9: 0 | K9: 0
A10: Remaining inventory (carryover out) | B10: =B8-B9 -> 11180.416 | C10: =C8-C9 -> 8900.9989 | D10: =D8-D9 -> 6334.4703 | E10: =E8-E9 -> 4553.5002 | F10: =F8-F9 -> 3013.4199 | G10: =G8-G9 -> 2250.0227 | H10: =H8-H9 -> 2021.9604 | I10: =I8-I9 -> 1819.7644 | ... K10: =K8-K9 -> 1474.0092
A12: Production Parameters Used
A13: Yield Factor (Mean) | B13: 1.0632
A14: Conversion Rate (Mean) | B14: 1.0428

Sheet Bayer__Above_below_105
A1: INVENTORY LIFECYCLE | Bayer - Above/below ground | Maturity 105 | Median Sales
A2: Line Item | B2: Year 1 | C2: Year 2 | D2: Year 3 | E2: Year 4 | F2: Year 5 | G2: Year 6 | H2: Year 7 | I2: Year 8 | J2: Year 9 | K2: Year 10
A3: Carryover inventory from prior year | B3: 10000 | C3: =B10 -> 11402.535 | D3: =C10 -> 8370.497 | E3: =D10 -> 4755.6581 | F3: =E10 -> 2106.9946 | G3: =F10 -> -264.23116 | H3: =G10 -> -1176.2969 | I3: =H10 -> -1312.6172 | J3: =I10 -> -1181.3555 | K3: =J10 -> -1063.22
A4: Carryover quality loss (10%) | B4: =-B3*Assumptions!$B$5 -> -1000 | C4: =-C3*Assumptions!$B$5 -> -1140.2535 | D4: =-D3*Assumptions!$B$5 -> -837.0497 | E4: =-E3*Assumptions!$B$5 -> -475.56581 | F4: =-F3*Assumptions!$B$5 -> -210.69946 | G4: =-G3*Assumptions!$B$5 -> 26.423116 | H4: =-H3*Assumptions!$B$5 -> 117.62969 | I4: =-I3*Assumptions!$B$5 -> 131.26172 | ... K4: =-K3*Assumptions!$B$5 -> 106.322
A5: Planned production (= next yr sales) | B5: 9973.67 | C5: 8180.42 | D5: 5468.5 | E5: 3335.58 | F5: 1189.38 | G5: 253.95 | H5: 0 | I5: 0 | J5: 0 | K5: 0
A6: New production (after yield & conv.) | B6: =B5*$B$13*$B$14 -> 10054.628 | C6: =C5*$B$13*$B$14 -> 8246.8217 | D6: =D5*$B$13*$B$14 -> 5512.8886 | E6: =E5*$B$13*$B$14 -> 3362.6554 | F6: =F5*$B$13*$B$14 -> 1199.0344 | G6: =G5*$B$13*$B$14 -> 256.01135 | H6: =H5*$B$13*$B$14 -> 0 | I6: =I5*$B$13*$B$14 -> 0 | ... K6: =K5*$B$13*$B$14 -> 0
A7: Production quality loss (2%) | B7: =-B6*Assumptions!$B$6 -> -201.09256 | C7: =-C6*Assumptions!$B$6 -> -164.93643 | D7: =-D6*Assumptions!$B$6 -> -110.25777 | E7: =-E6*Assumptions!$B$6 -> -67.253108 | F7: =-F6*Assumptions!$B$6 -> -23.980688 | G7: =-G6*Assumptions!$B$6 -> -5.120227 | H7: =-H6*Assumptions!$B$6 -> 0 | I7: =-I6*Assumptions!$B$6 -> 0 | ... K7: =-K6*Assumptions!$B$6 -> 0
A8: Total saleable inventory | B8: =B3+B4+B6+B7 -> 18853.535 | C8: =C3+C4+C6+C7 -> 18344.167 | D8: =D3+D4+D6+D7 -> 12936.078 | E8: =E3+E4+E6+E7 -> 7575.4946 | F8: =F3+F4+F6+F7 -> 3071.3488 | G8: =G3+G4+G6+G7 -> 13.083076 | H8: =H3+H4+H6+H7 -> -1058.6672 | I8: =I3+I4+I6+I7 -> -1181.3555 | ... K8: =K3+K4+K6+K7 -> -956.89796
A9: Sales | B9: 7451 | C9: 9973.67 | D9: 8180.42 | E9: 5468.5 | F9: 3335.58 | G9: 1189.38 | H9: 253.95 | I9: 0 | J9: 0 | K9: 0
A10: Remaining inventory (carryover out) | B10: =B8-B9 -> 11402.535 | C10: =C8-C9 -> 8370.497 | D10: =D8-D9 -> 4755.6581 | E10: =E8-E9 -> 2106.9946 | F10: =F8-F9 -> -264.23116 | G10: =G8-G9 -> -1176.2969 | H10: =H8-H9 -> -1312.6172 | I10: =I8-I9 -> -1181.3555 | ... K10: =K8-K9 -> -956.89796
A12: Production Parameters Used
A13: Yield Factor (Mean) | B13: 0.9465
A14: Conversion Rate (Mean) | B14: 1.0651

Sheet Bayer__Above_below_115
A1: INVENTORY LIFECYCLE | Bayer - Above/below ground | Maturity 115 | Median Sales
A2: Line Item | B2: Year 1 | C2: Year 2 | D2: Year 3 | E2: Year 4 | F2: Year 5 | G2: Year 6 | H2: Year 7 | I2: Year 8 | J2: Year 9 | K2: Year 10
A3: Carryover inventory from prior year | B3: 10000 | C3: =B10 -> 12291.015 | D3: =C10 -> 9364.2245 | E3: =D10 -> 5997.8373 | F3: =E10 -> 3299.1788 | G3: =F10 -> 920.29419 | H3: =G10 -> -147.6646 | I3: =H10 -> -385.26814 | J3: =I10 -> -346.74133 | K3: =J10 -> -312.06719
A4: Carryover quality loss (10%) | B4: =-B3*Assumptions!$B$5 -> -1000 | C4: =-C3*Assumptions!$B$5 -> -1229.1015 | D4: =-D3*Assumptions!$B$5 -> -936.42245 | E4: =-E3*Assumptions!$B$5 -> -599.78373 | F4: =-F3*Assumptions!$B$5 -> -329.91788 | G4: =-G3*Assumptions!$B$5 -> -92.029419 | H4: =-H3*Assumptions!$B$5 -> 14.76646 | I4: =-I3*Assumptions!$B$5 -> 38.526814 | ... K4: =-K3*Assumptions!$B$5 -> 31.206719
A5: Planned production (= next yr sales) | B5: 10170.47 | C5: 8178.82 | D5: 5549.4 | E5: 3330.81 | F5: 1237.37 | G5: 252.37 | H5: 0 | I5: 0 | J5: 0 | K5: 0
A6: New production (after yield & conv.) | B6: =B5*$B$13*$B$14 -> 10751.035 | C6: =C5*$B$13*$B$14 -> 8645.6952 | D6: =D5*$B$13*$B$14 -> 5866.1788 | E6: =E5*$B$13*$B$14 -> 3520.9441 | F6: =F5*$B$13*$B$14 -> 1308.0033 | G6: =G5*$B$13*$B$14 -> 266.77615 | H6: =H5*$B$13*$B$14 -> 0 | I6: =I5*$B$13*$B$14 -> 0 | ... K6: =K5*$B$13*$B$14 -> 0
A7: Production quality loss (2%) | B7: =-B6*Assumptions!$B$6 -> -215.02071 | C7: =-C6*Assumptions!$B$6 -> -172.9139 | D7: =-D6*Assumptions!$B$6 -> -117.32358 | E7: =-E6*Assumptions!$B$6 -> -70.418882 | F7: =-F6*Assumptions!$B$6 -> -26.160067 | G7: =-G6*Assumptions!$B$6 -> -5.335523 | H7: =-H6*Assumptions!$B$6 -> 0 | I7: =-I6*Assumptions!$B$6 -> 0 | ... K7: =-K6*Assumptions!$B$6 -> 0
A8: Total saleable inventory | B8: =B3+B4+B6+B7 -> 19536.015 | C8: =C3+C4+C6+C7 -> 19534.695 | D8: =D3+D4+D6+D7 -> 14176.657 | E8: =E3+E4+E6+E7 -> 8848.5788 | F8: =F3+F4+F6+F7 -> 4251.1042 | G8: =G3+G4+G6+G7 -> 1089.7054 | H8: =H3+H4+H6+H7 -> -132.89814 | I8: =I3+I4+I6+I7 -> -346.74133 | ... K8: =K3+K4+K6+K7 -> -280.86047
A9: Sales | B9: 7245 | C9: 10170.47 | D9: 8178.82 | E9: 5549.4 | F9: 3330.81 | G9: 1237.37 | H9: 252.37 | I9: 0 | J9: 0 | K9: 0
A10: Remaining inventory (carryover out) | B10: =B8-B9 -> 12291.015 | C10: =C8-C9 -> 9364.2245 | D10: =D8-D9 -> 5997.8373 | E10: =E8-E9 -> 3299.1788 | F10: =F8-F9 -> 920.29419 | G10: =G8-G9 -> -147.6646 | H10: =H8-H9 -> -385.26814 | I10: =I8-I9 -> -346.74133 | ... K10: =K8-K9 -> -280.86047
A12: Production Parameters Used
A13: Yield Factor (Mean) | B13: 1.0429
A14: Conversion Rate (Mean) | B14: 1.0136

Sheet Conventional_85
A1: INVENTORY LIFECYCLE | Conventional | Maturity 85 | Median Sales
A2: Line Item | B2: Year 1 | C2: Year 2 | D2: Year 3 | E2: Year 4 | F2: Year 5 | G2: Year 6 | H2: Year 7 | I2: Year 8 | J2: Year 9 | K2: Year 10
A3: Carryover inventory from prior year | B3: 10000 | C3: =B10 -> 10696.141 | D3: =C10 -> 9244.2488 | E3: =D10 -> 7582.595 | F3: =E10 -> 6251.1486 | G3: =F10 -> 5137.8427 | H3: =G10 -> 4599.7684 | I3: =H10 -> 4139.7916 | J3: =I10 -> 3725.8124 | K3: =J10 -> 3353.2312
A4: Carryover quality loss (10%) | B4: =-B3*Assumptions!$B$5 -> -1000 | C4: =-C3*Assumptions!$B$5 -> -1069.6141 | D4: =-D3*Assumptions!$B$5 -> -924.42488 | E4: =-E3*Assumptions!$B$5 -> -758.2595 | F4: =-F3*Assumptions!$B$5 -> -625.11486 | G4: =-G3*Assumptions!$B$5 -> -513.78427 | H4: =-H3*Assumptions!$B$5 -> -459.97684 | I4: =-I3*Assumptions!$B$5 -> -413.97916 | ... K4: =-K3*Assumptions!$B$5 -> -335.32312
A5: Planned production (= next yr sales) | B5: 2806.57 | C5: 2093.43 | D5: 1171.11 | E5: 516.32 | F5: 24.29 | G5: 0 | H5: 0 | I5: 0 | J5: 0 | K5: 0
A6: New production (after yield & conv.) | B6: =B5*$B$13*$B$14 -> 3316.4709 | C6: =C5*$B$13*$B$14 -> 2473.7668 | D6: =D5*$B$13*$B$14 -> 1383.8786 | E6: =E5*$B$13*$B$14 -> 610.12562 | F6: =F5*$B$13*$B$14 -> 28.703035 | G6: =G5*$B$13*$B$14 -> 0 | H6: =H5*$B$13*$B$14 -> 0 | I6: =I5*$B$13*$B$14 -> 0 | ... K6: =K5*$B$13*$B$14 -> 0
A7: Production quality loss (2%) | B7: =-B6*Assumptions!$B$6 -> -66.329418 | C7: =-C6*Assumptions!$B$6 -> -49.475336 | D7: =-D6*Assumptions!$B$6 -> -27.677572 | E7: =-E6*Assumptions!$B$6 -> -12.202512 | F7: =-F6*Assumptions!$B$6 -> -0.57406071 | G7: =-G6*Assumptions!$B$6 -> 0 | H7: =-H6*Assumptions!$B$6 -> 0 | I7: =-I6*Assumptions!$B$6 -> 0 | ... K7: =-K6*Assumptions!$B$6 -> 0
A8: Total saleable inventory | B8: =B3+B4+B6+B7 -> 12250.141 | C8: =C3+C4+C6+C7 -> 12050.819 | D8: =D3+D4+D6+D7 -> 9676.025 | E8: =E3+E4+E6+E7 -> 7422.2586 | F8: =F3+F4+F6+F7 -> 5654.1627 | G8: =G3+G4+G6+G7 -> 4624.0584 | H8: =H3+H4+H6+H7 -> 4139.7916 | I8: =I3+I4+I6+I7 -> 3725.8124 | ... K8: =K3+K4+K6+K7 -> 3017.9081
A9: Sales | B9: 1554 | C9: 2806.57 | D9: 2093.43 | E9: 1171.11 | F9: 516.32 | G9: 24.29 | H9: 0 | I9: 0 | J9: 0 | K9: 0
A10: Remaining inventory (carryover out) | B10: =B8-B9 -> 10696.141 | C10: =C8-C9 -> 9244.2488 | D10: =D8-D9 -> 7582.595 | E10: =E8-E9 -> 6251.1486 | F10: =F8-F9 -> 5137.8427 | G10: =G8-G9 -> 4599.7684 | H10: =H8-H9 -> 4139.7916 | I10: =I8-I9 -> 3725.8124 | ... K10: =K8-K9 -> 3017.9081
A12: Production Parameters Used
A13: Yield Factor (Mean) | B13: 1.1737
A14: Conversion Rate (Mean) | B14: 1.0068

Sheet Conventional_95
A1: INVENTORY LIFECYCLE | Conventional | Maturity 95 | Median Sales
A2: Line Item | B2: Year 1 | C2: Year 2 | D2: Year 3 | E2: Year 4 | F2: Year 5 | G2: Year 6 | H2: Year 7 | I2: Year 8 | J2: Year 9 | K2: Year 10
A3: Carryover inventory from prior year | B3: 10000 | C3: =B10 -> 10588.889 | D3: =C10 -> 8702.1447 | E3: =D10 -> 6675.6414 | F3: =E10 -> 5184.549 | G3: =F10 -> 3972.031 | H3: =G10 -> 3464.7279 | I3: =H10 -> 3118.2551 | J3: =I10 -> 2806.4296 | K3: =J10 -> 2525.7866
A4: Carryover quality loss (10%) | B4: =-B3*Assumptions!$B$5 -> -1000 | C4: =-C3*Assumptions!$B$5 -> -1058.8889 | D4: =-D3*Assumptions!$B$5 -> -870.21447 | E4: =-E3*Assumptions!$B$5 -> -667.56414 | F4: =-F3*Assumptions!$B$5 -> -518.4549 | G4: =-G3*Assumptions!$B$5 -> -397.2031 | H4: =-H3*Assumptions!$B$5 -> -346.47279 | I4: =-I3*Assumptions!$B$5 -> -311.82551 | ... K4: =-K3*Assumptions!$B$5 -> -252.57866
A5: Planned production (= next yr sales) | B5: 3831.82 | C5: 2887.85 | D5: 1664.63 | E5: 808.59 | F5: 110.1 | G5: 0 | H5: 0 | I5: 0 | J5: 0 | K5: 0
A6: New production (after yield & conv.) | B6: =B5*$B$13*$B$14 -> 4067.234 | C6: =C5*$B$13*$B$14 -> 3065.2697 | D6: =D5*$B$13*$B$14 -> 1766.8992 | E6: =E5*$B$13*$B$14 -> 858.26702 | F6: =F5*$B$13*$B$14 -> 116.86417 | G6: =G5*$B$13*$B$14 -> 0 | H6: =H5*$B$13*$B$14 -> 0 | I6: =I5*$B$13*$B$14 -> 0 | ... K6: =K5*$B$13*$B$14 -> 0
A7: Production quality loss (2%) | B7: =-B6*Assumptions!$B$6 -> -81.34468 | C7: =-C6*Assumptions!$B$6 -> -61.305394 | D7: =-D6*Assumptions!$B$6 -> -35.337984 | E7: =-E6*Assumptions!$B$6 -> -17.16534 | F7: =-F6*Assumptions!$B$6 -> -2.3372834 | G7: =-G6*Assumptions!$B$6 -> 0 | H7: =-H6*Assumptions!$B$6 -> 0 | I7: =-I6*Assumptions!$B$6 -> 0 | ... K7: =-K6*Assumptions!$B$6 -> 0
A8: Total saleable inventory | B8: =B3+B4+B6+B7 -> 12985.889 | C8: =C3+C4+C6+C7 -> 12533.965 | D8: =D3+D4+D6+D7 -> 9563.4914 | E8: =E3+E4+E6+E7 -> 6849.179 | F8: =F3+F4+F6+F7 -> 4780.621 | G8: =G3+G4+G6+G7 -> 3574.8279 | H8: =H3+H4+H6+H7 -> 3118.2551 | I8: =I3+I4+I6+I7 -> 2806.4296 | ... K8: =K3+K4+K6+K7 -> 2273.2079
A9: Sales | B9: 2397 | C9: 3831.82 | D9: 2887.85 | E9: 1664.63 | F9: 808.59 | G9: 110.1 | H9: 0 | I9: 0 | J9: 0 | K9: 0
A10: Remaining inventory (carryover out) | B10: =B8-B9 -> 10588.889 | C10: =C8-C9 -> 8702.1447 | D10: =D8-D9 -> 6675.6414 | E10: =E8-E9 -> 5184.549 | F10: =F8-F9 -> 3972.031 | G10: =G8-G9 -> 3464.7279 | H10: =H8-H9 -> 3118.2551 | I10: =I8-I9 -> 2806.4296 | ... K10: =K8-K9 -> 2273.2079
A12: Production Parameters Used
A13: Yield Factor (Mean) | B13: 1.098
A14: Conversion Rate (Mean) | B14: 0.9667

Sheet Conventional_105
A1: INVENTORY LIFECYCLE | Conventional | Maturity 105 | Median Sales
A2: Line Item | B2: Year 1 | C2: Year 2 | D2: Year 3 | E2: Year 4 | F2: Year 5 | G2: Year 6 | H2: Year 7 | I2: Year 8 | J2: Year 9 | K2: Year 10
A3: Carryover inventory from prior year | B3: 10000 | C3: =B10 -> 10085.373 | D3: =C10 -> 8004.3021 | E3: =D10 -> 5908.0254 | F3: =E10 -> 4320.5529 | G3: =F10 -> 2994.9755 | H3: =G10 -> 2458.378 | I3: =H10 -> 2212.5402 | J3: =I10 -> 1991.2861 | K3: =J10 -> 1792.1575
A4: Carryover quality loss (10%) | B4: =-B3*Assumptions!$B$5 -> -1000 | C4: =-C3*Assumptions!$B$5 -> -1008.5373 | D4: =-D3*Assumptions!$B$5 -> -800.43021 | E4: =-E3*Assumptions!$B$5 -> -590.80254 | F4: =-F3*Assumptions!$B$5 -> -432.05529 | G4: =-G3*Assumptions!$B$5 -> -299.49755 | H4: =-H3*Assumptions!$B$5 -> -245.8378 | I4: =-I3*Assumptions!$B$5 -> -221.25402 | ... K4: =-K3*Assumptions!$B$5 -> -179.21575
A5: Planned production (= next yr sales) | B5: 4516.08 | C5: 3433.44 | D5: 2131.32 | E5: 1131.32 | F5: 237.1 | G5: 0 | H5: 0 | I5: 0 | J5: 0 | K5: 0
A6: New production (after yield & conv.) | B6: =B5*$B$13*$B$14 -> 4621.8092 | C6: =C5*$B$13*$B$14 -> 3513.8228 | D6: =D5*$B$13*$B$14 -> 2181.2179 | E6: =E5*$B$13*$B$14 -> 1157.8062 | F6: =F5*$B$13*$B$14 -> 242.65092 | G6: =G5*$B$13*$B$14 -> 0 | H6: =H5*$B$13*$B$14 -> 0 | I6: =I5*$B$13*$B$14 -> 0 | ... K6: =K5*$B$13*$B$14 -> 0
A7: Production quality loss (2%) | B7: =-B6*Assumptions!$B$6 -> -92.436185 | C7: =-C6*Assumptions!$B$6 -> -70.276455 | D7: =-D6*Assumptions!$B$6 -> -43.624358 | E7: =-E6*Assumptions!$B$6 -> -23.156123 | F7: =-F6*Assumptions!$B$6 -> -4.8530184 | G7: =-G6*Assumptions!$B$6 -> 0 | H7: =-H6*Assumptions!$B$6 -> 0 | I7: =-I6*Assumptions!$B$6 -> 0 | ... K7: =-K6*Assumptions!$B$6 -> 0
A8: Total saleable inventory | B8: =B3+B4+B6+B7 -> 13529.373 | C8: =C3+C4+C6+C7 -> 12520.382 | D8: =D3+D4+D6+D7 -> 9341.4654 | E8: =E3+E4+E6+E7 -> 6451.8729 | F8: =F3+F4+F6+F7 -> 4126.2955 | G8: =G3+G4+G6+G7 -> 2695.478 | H8: =H3+H4+H6+H7 -> 2212.5402 | I8: =I3+I4+I6+I7 -> 1991.2861 | ... K8: =K3+K4+K6+K7 -> 1612.9418
A9: Sales | B9: 3444 | C9: 4516.08 | D9: 3433.44 | E9: 2131.32 | F9: 1131.32 | G9: 237.1 | H9: 0 | I9: 0 | J9: 0 | K9: 0
A10: Remaining inventory (carryover out) | B10: =B8-B9 -> 10085.373 | C10: =C8-C9 -> 8004.3021 | D10: =D8-D9 -> 5908.0254 | E10: =E8-E9 -> 4320.5529 | F10: =F8-F9 -> 2994.9755 | G10: =G8-G9 -> 2458.378 | H10: =H8-H9 -> 2212.5402 | I10: =I8-I9 -> 1991.2861 | ... K10: =K8-K9 -> 1612.9418
A12: Production Parameters Used
A13: Yield Factor (Mean) | B13: 1.0489
A14: Conversion Rate (Mean) | B14: 0.9757

Sheet Conventional_115
A1: INVENTORY LIFECYCLE | Conventional | Maturity 115 | Median Sales
A2: Line Item | B2: Year 1 | C2: Year 2 | D2: Year 3 | E2: Year 4 | F2: Year 5 | G2: Year 6 | H2: Year 7 | I2: Year 8 | J2: Year 9 | K2: Year 10
A3: Carryover inventory from prior year | B3: 10000 | C3: =B10 -> 10092.35 | D3: =C10 -> 7708.3714 | E3: =D10 -> 5461.9126 | F3: =E10 -> 3747.8771 | G3: =F10 -> 2451.4487 | H3: =G10 -> 1959.7138 | I3: =H10 -> 1763.7424 | J3: =I10 -> 1587.3682 | K3: =J10 -> 1428.6314
A4: Carryover quality loss (10%) | B4: =-B3*Assumptions!$B$5 -> -1000 | C4: =-C3*Assumptions!$B$5 -> -1009.235 | D4: =-D3*Assumptions!$B$5 -> -770.83714 | E4: =-E3*Assumptions!$B$5 -> -546.19126 | F4: =-F3*Assumptions!$B$5 -> -374.78771 | G4: =-G3*Assumptions!$B$5 -> -245.14487 | H4: =-H3*Assumptions!$B$5 -> -195.97138 | I4: =-I3*Assumptions!$B$5 -> -176.37424 | ... K4: =-K3*Assumptions!$B$5 -> -142.86314
A5: Planned production (= next yr sales) | B5: 4742.34 | C5: 3587.74 | D5: 2250.19 | E5: 1153.1 | F5: 246.59 | G5: 0 | H5: 0 | I5: 0 | J5: 0 | K5: 0
A6: New production (after yield & conv.) | B6: =B5*$B$13*$B$14 -> 4542.194 | C6: =C5*$B$13*$B$14 -> 3436.3228 | D6: =D5*$B$13*$B$14 -> 2155.2228 | E6: =E5*$B$13*$B$14 -> 1104.4345 | F6: =F5*$B$13*$B$14 -> 236.1829 | G6: =G5*$B$13*$B$14 -> 0 | H6: =H5*$B$13*$B$14 -> 0 | I6: =I5*$B$13*$B$14 -> 0 | ... K6: =K5*$B$13*$B$14 -> 0
A7: Production quality loss (2%) | B7: =-B6*Assumptions!$B$6 -> -90.843879 | C7: =-C6*Assumptions!$B$6 -> -68.726455 | D7: =-D6*Assumptions!$B$6 -> -43.104456 | E7: =-E6*Assumptions!$B$6 -> -22.08869 | F7: =-F6*Assumptions!$B$6 -> -4.723658 | G7: =-G6*Assumptions!$B$6 -> 0 | H7: =-H6*Assumptions!$B$6 -> 0 | I7: =-I6*Assumptions!$B$6 -> 0 | ... K7: =-K6*Assumptions!$B$6 -> 0
A8: Total saleable inventory | B8: =B3+B4+B6+B7 -> 13451.35 | C8: =C3+C4+C6+C7 -> 12450.711 | D8: =D3+D4+D6+D7 -> 9049.6526 | E8: =E3+E4+E6+E7 -> 5998.0671 | F8: =F3+F4+F6+F7 -> 3604.5487 | G8: =G3+G4+G6+G7 -> 2206.3038 | H8: =H3+H4+H6+H7 -> 1763.7424 | I8: =I3+I4+I6+I7 -> 1587.3682 | ... K8: =K3+K4+K6+K7 -> 1285.7682
A9: Sales | B9: 3359 | C9: 4742.34 | D9: 3587.74 | E9: 2250.19 | F9: 1153.1 | G9: 246.59 | H9: 0 | I9: 0 | J9: 0 | K9: 0
A10: Remaining inventory (carryover out) | B10: =B8-B9 -> 10092.35 | C10: =C8-C9 -> 7708.3714 | D10: =D8-D9 -> 5461.9126 | E10: =E8-E9 -> 3747.8771 | F10: =F8-F9 -> 2451.4487 | G10: =G8-G9 -> 1959.7138 | H10: =H8-H9 -> 1763.7424 | I10: =I8-I9 -> 1587.3682 | ... K10: =K8-K9 -> 1285.7682
A12: Production Parameters Used
A13: Yield Factor (Mean) | B13: 0.9863
A14: Conversion Rate (Mean) | B14: 0.9711

Sheet Syngenta__Above_gr_85
A1: INVENTORY LIFECYCLE | Syngenta - Above ground | Maturity 85 | Median Sales
A2: Line Item | B2: Year 1 | C2: Year 2 | D2: Year 3 | E2: Year 4 | F2: Year 5 | G2: Year 6 | H2: Year 7 | I2: Year 8 | J2: Year 9 | K2: Year 10
A3: Carryover inventory from prior year | B3: 10000 | C3: =B10 -> 9000 | D3: =C10 -> 8100 | E3: =D10 -> 7290 | F3: =E10 -> 6561 | G3: =F10 -> 5904.9 | H3: =G10 -> 5314.41 | I3: =H10 -> 4782.969 | J3: =I10 -> 4304.6721 | K3: =J10 -> 3874.2049
A4: Carryover quality loss (10%) | B4: =-B3*Assumptions!$B$5 -> -1000 | C4: =-C3*Assumptions!$B$5 -> -900 | D4: =-D3*Assumptions!$B$5 -> -810 | E4: =-E3*Assumptions!$B$5 -> -729 | F4: =-F3*Assumptions!$B$5 -> -656.1 | G4: =-G3*Assumptions!$B$5 -> -590.49 | H4: =-H3*Assumptions!$B$5 -> -531.441 | I4: =-I3*Assumptions!$B$5 -> -478.2969 | ... K4: =-K3*Assumptions!$B$5 -> -387.42049
A5: Planned production (= next yr sales) | B5: 0 | C5: 0 | D5: 0 | E5: 0 | F5: 0 | G5: 0 | H5: 0 | I5: 0 | J5: 0 | K5: 0
A6: New production (after yield & conv.) | B6: =B5*$B$13*$B$14 -> 0 | C6: =C5*$B$13*$B$14 -> 0 | D6: =D5*$B$13*$B$14 -> 0 | E6: =E5*$B$13*$B$14 -> 0 | F6: =F5*$B$13*$B$14 -> 0 | G6: =G5*$B$13*$B$14 -> 0 | H6: =H5*$B$13*$B$14 -> 0 | I6: =I5*$B$13*$B$14 -> 0 | ... K6: =K5*$B$13*$B$14 -> 0
A7: Production quality loss (2%) | B7: =-B6*Assumptions!$B$6 -> 0 | C7: =-C6*Assumptions!$B$6 -> 0 | D7: =-D6*Assumptions!$B$6 -> 0 | E7: =-E6*Assumptions!$B$6 -> 0 | F7: =-F6*Assumptions!$B$6 -> 0 | G7: =-G6*Assumptions!$B$6 -> 0 | H7: =-H6*Assumptions!$B$6 -> 0 | I7: =-I6*Assumptions!$B$6 -> 0 | ... K7: =-K6*Assumptions!$B$6 -> 0
A8: Total saleable inventory | B8: =B3+B4+B6+B7 -> 9000 | C8: =C3+C4+C6+C7 -> 8100 | D8: =D3+D4+D6+D7 -> 7290 | E8: =E3+E4+E6+E7 -> 6561 | F8: =F3+F4+F6+F7 -> 5904.9 | G8: =G3+G4+G6+G7 -> 5314.41 | H8: =H3+H4+H6+H7 -> 4782.969 | I8: =I3+I4+I6+I7 -> 4304.6721 | ... K8: =K3+K4+K6+K7 -> 3486.7844
A9: Sales | B9: 0 | C9: 0 | D9: 0 | E9: 0 | F9: 0 | G9: 0 | H9: 0 | I9: 0 | J9: 0 | K9: 0
A10: Remaining inventory (carryover out) | B10: =B8-B9 -> 9000 | C10: =C8-C9 -> 8100 | D10: =D8-D9 -> 7290 | E10: =E8-E9 -> 6561 | F10: =F8-F9 -> 5904.9 | G10: =G8-G9 -> 5314.41 | H10: =H8-H9 -> 4782.969 | I10: =I8-I9 -> 4304.6721 | ... K10: =K8-K9 -> 3486.7844
A12: Production Parameters Used
A13: Yield Factor (Mean) | B13: 1.1885
A14: Conversion Rate (Mean) | B14: 1.1019

Sheet Syngenta__Above_gr_95
A1: INVENTORY LIFECYCLE | Syngenta - Above ground | Maturity 95 | Median Sales
A2: Line Item | B2: Year 1 | C2: Year 2 | D2: Year 3 | E2: Year 4 | F2: Year 5 | G2: Year 6 | H2: Year 7 | I2: Year 8 | J2: Year 9 | K2: Year 10
A3: Carryover inventory from prior year | B3: 10000 | C3: =B10 -> 9000 | D3: =C10 -> 8100 | E3: =D10 -> 7290 | F3: =E10 -> 6561 | G3: =F10 -> 5904.9 | H3: =G10 -> 5314.41 | I3: =H10 -> 4782.969 | J3: =I10 -> 4304.6721 | K3: =J10 -> 3874.2049
A4: Carryover quality loss (10%) | B4: =-B3*Assumptions!$B$5 -> -1000 | C4: =-C3*Assumptions!$B$5 -> -900 | D4: =-D3*Assumptions!$B$5 -> -810 | E4: =-E3*Assumptions!$B$5 -> -729 | F4: =-F3*Assumptions!$B$5 -> -656.1 | G4: =-G3*Assumptions!$B$5 -> -590.49 | H4: =-H3*Assumptions!$B$5 -> -531.441 | I4: =-I3*Assumptions!$B$5 -> -478.2969 | ... K4: =-K3*Assumptions!$B$5 -> -387.42049
A5: Planned production (= next yr sales) | B5: 0 | C5: 0 | D5: 0 | E5: 0 | F5: 0 | G5: 0 | H5: 0 | I5: 0 | J5: 0 | K5: 0
A6: New production (after yield & conv.) | B6: =B5*$B$13*$B$14 -> 0 | C6: =C5*$B$13*$B$14 -> 0 | D6: =D5*$B$13*$B$14 -> 0 | E6: =E5*$B$13*$B$14 -> 0 | F6: =F5*$B$13*$B$14 -> 0 | G6: =G5*$B$13*$B$14 -> 0 | H6: =H5*$B$13*$B$14 -> 0 | I6: =I5*$B$13*$B$14 -> 0 | ... K6: =K5*$B$13*$B$14 -> 0
A7: Production quality loss (2%) | B7: =-B6*Assumptions!$B$6 -> 0 | C7: =-C6*Assumptions!$B$6 -> 0 | D7: =-D6*Assumptions!$B$6 -> 0 | E7: =-E6*Assumptions!$B$6 -> 0 | F7: =-F6*Assumptions!$B$6 -> 0 | G7: =-G6*Assumptions!$B$6 -> 0 | H7: =-H6*Assumptions!$B$6 -> 0 | I7: =-I6*Assumptions!$B$6 -> 0 | ... K7: =-K6*Assumptions!$B$6 -> 0
A8: Total saleable inventory | B8: =B3+B4+B6+B7 -> 9000 | C8: =C3+C4+C6+C7 -> 8100 | D8: =D3+D4+D6+D7 -> 7290 | E8: =E3+E4+E6+E7 -> 6561 | F8: =F3+F4+F6+F7 -> 5904.9 | G8: =G3+G4+G6+G7 -> 5314.41 | H8: =H3+H4+H6+H7 -> 4782.969 | I8: =I3+I4+I6+I7 -> 4304.6721 | ... K8: =K3+K4+K6+K7 -> 3486.7844
A9: Sales | B9: 0 | C9: 0 | D9: 0 | E9: 0 | F9: 0 | G9: 0 | H9: 0 | I9: 0 | J9: 0 | K9: 0
A10: Remaining inventory (carryover out) | B10: =B8-B9 -> 9000 | C10: =C8-C9 -> 8100 | D10: =D8-D9 -> 7290 | E10: =E8-E9 -> 6561 | F10: =F8-F9 -> 5904.9 | G10: =G8-G9 -> 5314.41 | H10: =H8-H9 -> 4782.969 | I10: =I8-I9 -> 4304.6721 | ... K10: =K8-K9 -> 3486.7844
A12: Production Parameters Used
A13: Yield Factor (Mean) | B13: 1.1505
A14: Conversion Rate (Mean) | B14: 1.0809

Sheet Syngenta__Above_gr_105
A1: INVENTORY LIFECYCLE | Syngenta - Above ground | Maturity 105 | Median Sales
A2: Line Item | B2: Year 1 | C2: Year 2 | D2: Year 3 | E2: Year 4 | F2: Year 5 | G2: Year 6 | H2: Year 7 | I2: Year 8 | J2: Year 9 | K2: Year 10
A3: Carryover inventory from prior year | B3: 10000 | C3: =B10 -> 9000 | D3: =C10 -> 8100 | E3: =D10 -> 7290 | F3: =E10 -> 6561 | G3: =F10 -> 5904.9 | H3: =G10 -> 5314.41 | I3: =H10 -> 4782.969 | J3: =I10 -> 4304.6721 | K3: =J10 -> 3874.2049
A4: Carryover quality loss (10%) | B4: =-B3*Assumptions!$B$5 -> -1000 | C4: =-C3*Assumptions!$B$5 -> -900 | D4: =-D3*Assumptions!$B$5 -> -810 | E4: =-E3*Assumptions!$B$5 -> -729 | F4: =-F3*Assumptions!$B$5 -> -656.1 | G4: =-G3*Assumptions!$B$5 -> -590.49 | H4: =-H3*Assumptions!$B$5 -> -531.441 | I4: =-I3*Assumptions!$B$5 -> -478.2969 | ... K4: =-K3*Assumptions!$B$5 -> -387.42049
A5: Planned production (= next yr sales) | B5: 0 | C5: 0 | D5: 0 | E5: 0 | F5: 0 | G5: 0 | H5: 0 | I5: 0 | J5: 0 | K5: 0
A6: New production (after yield & conv.) | B6: =B5*$B$13*$B$14 -> 0 | C6: =C5*$B$13*$B$14 -> 0 | D6: =D5*$B$13*$B$14 -> 0 | E6: =E5*$B$13*$B$14 -> 0 | F6: =F5*$B$13*$B$14 -> 0 | G6: =G5*$B$13*$B$14 -> 0 | H6: =H5*$B$13*$B$14 -> 0 | I6: =I5*$B$13*$B$14 -> 0 | ... K6: =K5*$B$13*$B$14 -> 0
A7: Production quality loss (2%) | B7: =-B6*Assumptions!$B$6 -> 0 | C7: =-C6*Assumptions!$B$6 -> 0 | D7: =-D6*Assumptions!$B$6 -> 0 | E7: =-E6*Assumptions!$B$6 -> 0 | F7: =-F6*Assumptions!$B$6 -> 0 | G7: =-G6*Assumptions!$B$6 -> 0 | H7: =-H6*Assumptions!$B$6 -> 0 | I7: =-I6*Assumptions!$B$6 -> 0 | ... K7: =-K6*Assumptions!$B$6 -> 0
A8: Total saleable inventory | B8: =B3+B4+B6+B7 -> 9000 | C8: =C3+C4+C6+C7 -> 8100 | D8: =D3+D4+D6+D7 -> 7290 | E8: =E3+E4+E6+E7 -> 6561 | F8: =F3+F4+F6+F7 -> 5904.9 | G8: =G3+G4+G6+G7 -> 5314.41 | H8: =H3+H4+H6+H7 -> 4782.969 | I8: =I3+I4+I6+I7 -> 4304.6721 | ... K8: =K3+K4+K6+K7 -> 3486.7844
A9: Sales | B9: 0 | C9: 0 | D9: 0 | E9: 0 | F9: 0 | G9: 0 | H9: 0 | I9: 0 | J9: 0 | K9: 0
A10: Remaining inventory (carryover out) | B10: =B8-B9 -> 9000 | C10: =C8-C9 -> 8100 | D10: =D8-D9 -> 7290 | E10: =E8-E9 -> 6561 | F10: =F8-F9 -> 5904.9 | G10: =G8-G9 -> 5314.41 | H10: =H8-H9 -> 4782.969 | I10: =I8-I9 -> 4304.6721 | ... K10: =K8-K9 -> 3486.7844
A12: Production Parameters Used
A13: Yield Factor (Mean) | B13: 0.8745
A14: Conversion Rate (Mean) | B14: 0.9491

Sheet Syngenta__Above_gr_115
A1: INVENTORY LIFECYCLE | Syngenta - Above ground | Maturity 115 | Median Sales
A2: Line Item | B2: Year 1 | C2: Year 2 | D2: Year 3 | E2: Year 4 | F2: Year 5 | G2: Year 6 | H2: Year 7 | I2: Year 8 | J2: Year 9 | K2: Year 10
A3: Carryover inventory from prior year | B3: 10000 | C3: =B10 -> 9000 | D3: =C10 -> 8100 | E3: =D10 -> 7290 | F3: =E10 -> 6561 | G3: =F10 -> 5904.9 | H3: =G10 -> 5314.41 | I3: =H10 -> 4782.969 | J3: =I10 -> 4304.6721 | K3: =J10 -> 3874.2049
A4: Carryover quality loss (10%) | B4: =-B3*Assumptions!$B$5 -> -1000 | C4: =-C3*Assumptions!$B$5 -> -900 | D4: =-D3*Assumptions!$B$5 -> -810 | E4: =-E3*Assumptions!$B$5 -> -729 | F4: =-F3*Assumptions!$B$5 -> -656.1 | G4: =-G3*Assumptions!$B$5 -> -590.49 | H4: =-H3*Assumptions!$B$5 -> -531.441 | I4: =-I3*Assumptions!$B$5 -> -478.2969 | ... K4: =-K3*Assumptions!$B$5 -> -387.42049
A5: Planned production (= next yr sales) | B5: 0 | C5: 0 | D5: 0 | E5: 0 | F5: 0 | G5: 0 | H5: 0 | I5: 0 | J5: 0 | K5: 0
A6: New production (after yield & conv.) | B6: =B5*$B$13*$B$14 -> 0 | C6: =C5*$B$13*$B$14 -> 0 | D6: =D5*$B$13*$B$14 -> 0 | E6: =E5*$B$13*$B$14 -> 0 | F6: =F5*$B$13*$B$14 -> 0 | G6: =G5*$B$13*$B$14 -> 0 | H6: =H5*$B$13*$B$14 -> 0 | I6: =I5*$B$13*$B$14 -> 0 | ... K6: =K5*$B$13*$B$14 -> 0
A7: Production quality loss (2%) | B7: =-B6*Assumptions!$B$6 -> 0 | C7: =-C6*Assumptions!$B$6 -> 0 | D7: =-D6*Assumptions!$B$6 -> 0 | E7: =-E6*Assumptions!$B$6 -> 0 | F7: =-F6*Assumptions!$B$6 -> 0 | G7: =-G6*Assumptions!$B$6 -> 0 | H7: =-H6*Assumptions!$B$6 -> 0 | I7: =-I6*Assumptions!$B$6 -> 0 | ... K7: =-K6*Assumptions!$B$6 -> 0
A8: Total saleable inventory | B8: =B3+B4+B6+B7 -> 9000 | C8: =C3+C4+C6+C7 -> 8100 | D8: =D3+D4+D6+D7 -> 7290 | E8: =E3+E4+E6+E7 -> 6561 | F8: =F3+F4+F6+F7 -> 5904.9 | G8: =G3+G4+G6+G7 -> 5314.41 | H8: =H3+H4+H6+H7 -> 4782.969 | I8: =I3+I4+I6+I7 -> 4304.6721 | ... K8: =K3+K4+K6+K7 -> 3486.7844
A9: Sales | B9: 0 | C9: 0 | D9: 0 | E9: 0 | F9: 0 | G9: 0 | H9: 0 | I9: 0 | J9: 0 | K9: 0
A10: Remaining inventory (carryover out) | B10: =B8-B9 -> 9000 | C10: =C8-C9 -> 8100 | D10: =D8-D9 -> 7290 | E10: =E8-E9 -> 6561 | F10: =F8-F9 -> 5904.9 | G10: =G8-G9 -> 5314.41 | H10: =H8-H9 -> 4782.969 | I10: =I8-I9 -> 4304.6721 | ... K10: =K8-K9 -> 3486.7844
A12: Production Parameters Used
A13: Yield Factor (Mean) | B13: 0.8348
A14: Conversion Rate (Mean) | B14: 1.0263

Sheet Syngenta__Above_be_85
A1: INVENTORY LIFECYCLE | Syngenta - Above/below ground | Maturity 85 | Median Sales
A2: Line Item | B2: Year 1 | C2: Year 2 | D2: Year 3 | E2: Year 4 | F2: Year 5 | G2: Year 6 | H2: Year 7 | I2: Year 8 | J2: Year 9 | K2: Year 10
A3: Carryover inventory from prior year | B3: 10000 | C3: =B10 -> 9000 | D3: =C10 -> 8100 | E3: =D10 -> 7290 | F3: =E10 -> 6561 | G3: =F10 -> 5904.9 | H3: =G10 -> 5314.41 | I3: =H10 -> 4782.969 | J3: =I10 -> 4304.6721 | K3: =J10 -> 3874.2049
A4: Carryover quality loss (10%) | B4: =-B3*Assumptions!$B$5 -> -1000 | C4: =-C3*Assumptions!$B$5 -> -900 | D4: =-D3*Assumptions!$B$5 -> -810 | E4: =-E3*Assumptions!$B$5 -> -729 | F4: =-F3*Assumptions!$B$5 -> -656.1 | G4: =-G3*Assumptions!$B$5 -> -590.49 | H4: =-H3*Assumptions!$B$5 -> -531.441 | I4: =-I3*Assumptions!$B$5 -> -478.2969 | ... K4: =-K3*Assumptions!$B$5 -> -387.42049
A5: Planned production (= next yr sales) | B5: 0 | C5: 0 | D5: 0 | E5: 0 | F5: 0 | G5: 0 | H5: 0 | I5: 0 | J5: 0 | K5: 0
A6: New production (after yield & conv.) | B6: =B5*$B$13*$B$14 -> 0 | C6: =C5*$B$13*$B$14 -> 0 | D6: =D5*$B$13*$B$14 -> 0 | E6: =E5*$B$13*$B$14 -> 0 | F6: =F5*$B$13*$B$14 -> 0 | G6: =G5*$B$13*$B$14 -> 0 | H6: =H5*$B$13*$B$14 -> 0 | I6: =I5*$B$13*$B$14 -> 0 | ... K6: =K5*$B$13*$B$14 -> 0
A7: Production quality loss (2%) | B7: =-B6*Assumptions!$B$6 -> 0 | C7: =-C6*Assumptions!$B$6 -> 0 | D7: =-D6*Assumptions!$B$6 -> 0 | E7: =-E6*Assumptions!$B$6 -> 0 | F7: =-F6*Assumptions!$B$6 -> 0 | G7: =-G6*Assumptions!$B$6 -> 0 | H7: =-H6*Assumptions!$B$6 -> 0 | I7: =-I6*Assumptions!$B$6 -> 0 | ... K7: =-K6*Assumptions!$B$6 -> 0
A8: Total saleable inventory | B8: =B3+B4+B6+B7 -> 9000 | C8: =C3+C4+C6+C7 -> 8100 | D8: =D3+D4+D6+D7 -> 7290 | E8: =E3+E4+E6+E7 -> 6561 | F8: =F3+F4+F6+F7 -> 5904.9 | G8: =G3+G4+G6+G7 -> 5314.41 | H8: =H3+H4+H6+H7 -> 4782.969 | I8: =I3+I4+I6+I7 -> 4304.6721 | ... K8: =K3+K4+K6+K7 -> 3486.7844
A9: Sales | B9: 0 | C9: 0 | D9: 0 | E9: 0 | F9: 0 | G9: 0 | H9: 0 | I9: 0 | J9: 0 | K9: 0
A10: Remaining inventory (carryover out) | B10: =B8-B9 -> 9000 | C10: =C8-C9 -> 8100 | D10: =D8-D9 -> 7290 | E10: =E8-E9 -> 6561 | F10: =F8-F9 -> 5904.9 | G10: =G8-G9 -> 5314.41 | H10: =H8-H9 -> 4782.969 | I10: =I8-I9 -> 4304.6721 | ... K10: =K8-K9 -> 3486.7844
A12: Production Parameters Used
A13: Yield Factor (Mean) | B13: 1
A14: Conversion Rate (Mean) | B14: 1

Sheet Syngenta__Above_be_95
A1: INVENTORY LIFECYCLE | Syngenta - Above/below ground | Maturity 95 | Median Sales
A2: Line Item | B2: Year 1 | C2: Year 2 | D2: Year 3 | E2: Year 4 | F2: Year 5 | G2: Year 6 | H2: Year 7 | I2: Year 8 | J2: Year 9 | K2: Year 10
A3: Carryover inventory from prior year | B3: 10000 | C3: =B10 -> 9000 | D3: =C10 -> 8100 | E3: =D10 -> 7290 | F3: =E10 -> 6561 | G3: =F10 -> 5904.9 | H3: =G10 -> 5314.41 | I3: =H10 -> 4782.969 | J3: =I10 -> 4304.6721 | K3: =J10 -> 3874.2049
A4: Carryover quality loss (10%) | B4: =-B3*Assumptions!$B$5 -> -1000 | C4: =-C3*Assumptions!$B$5 -> -900 | D4: =-D3*Assumptions!$B$5 -> -810 | E4: =-E3*Assumptions!$B$5 -> -729 | F4: =-F3*Assumptions!$B$5 -> -656.1 | G4: =-G3*Assumptions!$B$5 -> -590.49 | H4: =-H3*Assumptions!$B$5 -> -531.441 | I4: =-I3*Assumptions!$B$5 -> -478.2969 | ... K4: =-K3*Assumptions!$B$5 -> -387.42049
A5: Planned production (= next yr sales) | B5: 0 | C5: 0 | D5: 0 | E5: 0 | F5: 0 | G5: 0 | H5: 0 | I5: 0 | J5: 0 | K5: 0
A6: New production (after yield & conv.) | B6: =B5*$B$13*$B$14 -> 0 | C6: =C5*$B$13*$B$14 -> 0 | D6: =D5*$B$13*$B$14 -> 0 | E6: =E5*$B$13*$B$14 -> 0 | F6: =F5*$B$13*$B$14 -> 0 | G6: =G5*$B$13*$B$14 -> 0 | H6: =H5*$B$13*$B$14 -> 0 | I6: =I5*$B$13*$B$14 -> 0 | ... K6: =K5*$B$13*$B$14 -> 0
A7: Production quality loss (2%) | B7: =-B6*Assumptions!$B$6 -> 0 | C7: =-C6*Assumptions!$B$6 -> 0 | D7: =-D6*Assumptions!$B$6 -> 0 | E7: =-E6*Assumptions!$B$6 -> 0 | F7: =-F6*Assumptions!$B$6 -> 0 | G7: =-G6*Assumptions!$B$6 -> 0 | H7: =-H6*Assumptions!$B$6 -> 0 | I7: =-I6*Assumptions!$B$6 -> 0 | ... K7: =-K6*Assumptions!$B$6 -> 0
A8: Total saleable inventory | B8: =B3+B4+B6+B7 -> 9000 | C8: =C3+C4+C6+C7 -> 8100 | D8: =D3+D4+D6+D7 -> 7290 | E8: =E3+E4+E6+E7 -> 6561 | F8: =F3+F4+F6+F7 -> 5904.9 | G8: =G3+G4+G6+G7 -> 5314.41 | H8: =H3+H4+H6+H7 -> 4782.969 | I8: =I3+I4+I6+I7 -> 4304.6721 | ... K8: =K3+K4+K6+K7 -> 3486.7844
A9: Sales | B9: 0 | C9: 0 | D9: 0 | E9: 0 | F9: 0 | G9: 0 | H9: 0 | I9: 0 | J9: 0 | K9: 0
A10: Remaining inventory (carryover out) | B10: =B8-B9 -> 9000 | C10: =C8-C9 -> 8100 | D10: =D8-D9 -> 7290 | E10: =E8-E9 -> 6561 | F10: =F8-F9 -> 5904.9 | G10: =G8-G9 -> 5314.41 | H10: =H8-H9 -> 4782.969 | I10: =I8-I9 -> 4304.6721 | ... K10: =K8-K9 -> 3486.7844
A12: Production Parameters Used
A13: Yield Factor (Mean) | B13: 0.9645
A14: Conversion Rate (Mean) | B14: 1.0723

Sheet Syngenta__Above_be_105
A1: INVENTORY LIFECYCLE | Syngenta - Above/below ground | Maturity 105 | Median Sales
A2: Line Item | B2: Year 1 | C2: Year 2 | D2: Year 3 | E2: Year 4 | F2: Year 5 | G2: Year 6 | H2: Year 7 | I2: Year 8 | J2: Year 9 | K2: Year 10
A3: Carryover inventory from prior year | B3: 10000 | C3: =B10 -> 9000 | D3: =C10 -> 8100 | E3: =D10 -> 7290 | F3: =E10 -> 6561 | G3: =F10 -> 5904.9 | H3: =G10 -> 5314.41 | I3: =H10 -> 4782.969 | J3: =I10 -> 4304.6721 | K3: =J10 -> 3874.2049
A4: Carryover quality loss (10%) | B4: =-B3*Assumptions!$B$5 -> -1000 | C4: =-C3*Assumptions!$B$5 -> -900 | D4: =-D3*Assumptions!$B$5 -> -810 | E4: =-E3*Assumptions!$B$5 -> -729 | F4: =-F3*Assumptions!$B$5 -> -656.1 | G4: =-G3*Assumptions!$B$5 -> -590.49 | H4: =-H3*Assumptions!$B$5 -> -531.441 | I4: =-I3*Assumptions!$B$5 -> -478.2969 | ... K4: =-K3*Assumptions!$B$5 -> -387.42049
A5: Planned production (= next yr sales) | B5: 0 | C5: 0 | D5: 0 | E5: 0 | F5: 0 | G5: 0 | H5: 0 | I5: 0 | J5: 0 | K5: 0
A6: New production (after yield & conv.) | B6: =B5*$B$13*$B$14 -> 0 | C6: =C5*$B$13*$B$14 -> 0 | D6: =D5*$B$13*$B$14 -> 0 | E6: =E5*$B$13*$B$14 -> 0 | F6: =F5*$B$13*$B$14 -> 0 | G6: =G5*$B$13*$B$14 -> 0 | H6: =H5*$B$13*$B$14 -> 0 | I6: =I5*$B$13*$B$14 -> 0 | ... K6: =K5*$B$13*$B$14 -> 0
A7: Production quality loss (2%) | B7: =-B6*Assumptions!$B$6 -> 0 | C7: =-C6*Assumptions!$B$6 -> 0 | D7: =-D6*Assumptions!$B$6 -> 0 | E7: =-E6*Assumptions!$B$6 -> 0 | F7: =-F6*Assumptions!$B$6 -> 0 | G7: =-G6*Assumptions!$B$6 -> 0 | H7: =-H6*Assumptions!$B$6 -> 0 | I7: =-I6*Assumptions!$B$6 -> 0 | ... K7: =-K6*Assumptions!$B$6 -> 0
A8: Total saleable inventory | B8: =B3+B4+B6+B7 -> 9000 | C8: =C3+C4+C6+C7 -> 8100 | D8: =D3+D4+D6+D7 -> 7290 | E8: =E3+E4+E6+E7 -> 6561 | F8: =F3+F4+F6+F7 -> 5904.9 | G8: =G3+G4+G6+G7 -> 5314.41 | H8: =H3+H4+H6+H7 -> 4782.969 | I8: =I3+I4+I6+I7 -> 4304.6721 | ... K8: =K3+K4+K6+K7 -> 3486.7844
A9: Sales | B9: 0 | C9: 0 | D9: 0 | E9: 0 | F9: 0 | G9: 0 | H9: 0 | I9: 0 | J9: 0 | K9: 0
A10: Remaining inventory (carryover out) | B10: =B8-B9 -> 9000 | C10: =C8-C9 -> 8100 | D10: =D8-D9 -> 7290 | E10: =E8-E9 -> 6561 | F10: =F8-F9 -> 5904.9 | G10: =G8-G9 -> 5314.41 | H10: =H8-H9 -> 4782.969 | I10: =I8-I9 -> 4304.6721 | ... K10: =K8-K9 -> 3486.7844
A12: Production Parameters Used
A13: Yield Factor (Mean) | B13: 0.9208
A14: Conversion Rate (Mean) | B14: 1.017

Sheet Syngenta__Above_be_115
A1: INVENTORY LIFECYCLE | Syngenta - Above/below ground | Maturity 115 | Median Sales
A2: Line Item | B2: Year 1 | C2: Year 2 | D2: Year 3 | E2: Year 4 | F2: Year 5 | G2: Year 6 | H2: Year 7 | I2: Year 8 | J2: Year 9 | K2: Year 10
A3: Carryover inventory from prior year | B3: 10000 | C3: =B10 -> 9000 | D3: =C10 -> 8100 | E3: =D10 -> 7290 | F3: =E10 -> 6561 | G3: =F10 -> 5904.9 | H3: =G10 -> 5314.41 | I3: =H10 -> 4782.969 | J3: =I10 -> 4304.6721 | K3: =J10 -> 3874.2049
